<?xml version='1.0' encoding='utf-8'?>
<robot name="go2_widow_description">
  <material name="black">
    <color rgba="0.0 0.0 0.0 1.0" />
  </material>
  <material name="blue">
    <color rgba="0.0 0.0 0.8 1.0" />
  </material>
  <material name="green">
    <color rgba="0.0 0.8 0.0 1.0" />
  </material>
  <material name="grey">
    <color rgba="0.2 0.2 0.2 1.0" />
  </material>
  <material name="silver">
    <color rgba="0.913725490196 0.913725490196 0.847058823529 1.0" />
  </material>
  <material name="orange">
    <color rgba="1.0 0.423529411765 0.0392156862745 1.0" />
  </material>
  <material name="brown">
    <color rgba="0.870588235294 0.811764705882 0.764705882353 1.0" />
  </material>
  <material name="red">
    <color rgba="0.8 0.0 0.0 1.0" />
  </material>
  <material name="white">
    <color rgba="1.0 1.0 1.0 1.0" />
  </material>

  <!-- ═══════════════════════ BASE ═══════════════════════ -->
  <link name="base">
    <inertial>
      <origin xyz="0.021112 0 -0.005366" rpy="0 0 0" />
      <mass value="6.921" />
      <inertia ixx="0.02448" ixy="0.00012166" ixz="0.0014849" iyy="0.098077" iyz="-3.12E-05" izz="0.107" />
    </inertial>
    <visual>
      <origin xyz="0 0 0" rpy="0 0 0" />
      <geometry>
        <mesh filename="../meshes/base.dae" />
      </geometry>
    </visual>
    <collision>
      <origin rpy="0 0 0" xyz="0 0 0" />
      <geometry>
        <box size="0.3762 0.0935 0.114" />
      </geometry>
    </collision>
  </link>

  <link name="Head_upper">
    <inertial>
      <origin xyz="0 0 0" rpy="0 0 0" />
      <mass value="0.001" />
      <inertia ixx="9.6e-06" ixy="0" ixz="0" iyy="9.6e-06" iyz="0" izz="9.6e-06" />
    </inertial>
    <collision>
      <origin xyz="0 0 0" rpy="0 0 0" />
      <geometry>
        <cylinder radius="0.05" length="0.09" />
      </geometry>
    </collision>
  </link>

  <link name="Head_lower">
    <inertial>
      <origin xyz="0 0 0" rpy="0 0 0" />
      <mass value="0.001" />
      <inertia ixx="9.6e-06" ixy="0" ixz="0" iyy="9.6e-06" iyz="0" izz="9.6e-06" />
    </inertial>
    <collision>
      <origin xyz="0 0 0" rpy="0 0 0" />
      <geometry>
        <sphere radius="0.047" />
      </geometry>
    </collision>
  </link>

  <!-- ═══════════════════════ LEGS ═══════════════════════ -->
  <link name="FL_hip">
    <inertial>
      <origin xyz="-0.0054 0.00194 -0.000105" rpy="0 0 0" />
      <mass value="0.678" />
      <inertia ixx="0.00048" ixy="-3.01E-06" ixz="1.11E-06" iyy="0.000884" iyz="-1.42E-06" izz="0.000596" />
    </inertial>
    <visual>
      <origin xyz="0 0 0" rpy="0 0 0" />
      <geometry>
        <mesh filename="../meshes/hip.dae" />
      </geometry>
    </visual>
    <collision>
      <origin rpy="1.5707963267948966 0 0" xyz="0 0.08 0" />
      <geometry>
        <cylinder length="0.04" radius="0.046" />
      </geometry>
    </collision>
  </link>
  <link name="FL_thigh">
    <inertial>
      <origin xyz="-0.00374 -0.0223 -0.0327" rpy="0 0 0" />
      <mass value="1.152" />
      <inertia ixx="0.00584" ixy="8.72E-05" ixz="-0.000289" iyy="0.0058" iyz="0.000808" izz="0.00103" />
    </inertial>
    <visual>
      <origin xyz="0 0 0" rpy="0 0 0" />
      <geometry>
        <mesh filename="../meshes/thigh.dae" />
      </geometry>
    </visual>
    <collision>
      <origin rpy="0 1.5707963267948966 0" xyz="0 0 -0.1065" />
      <geometry>
        <box size="0.11 0.0245 0.034" />
      </geometry>
    </collision>
  </link>
  <link name="FL_calf">
    <inertial>
      <origin xyz="0.00548 -0.000975 -0.115" rpy="0 0 0" />
      <mass value="0.154" />
      <inertia ixx="0.00108" ixy="3.4E-07" ixz="1.72E-05" iyy="0.0011" iyz="8.28E-06" izz="3.29E-05" />
    </inertial>
    <visual>
      <origin xyz="0 0 0" rpy="0 0 0" />
      <geometry>
        <mesh filename="../meshes/calf.dae" />
      </geometry>
    </visual>
    <collision>
      <origin rpy="0 -0.21 0" xyz="0.008 0 -0.06" />
      <geometry>
        <cylinder length="0.12" radius="0.012" />
      </geometry>
    </collision>
  </link>
  <link name="FL_calflower">
    <collision>
      <origin rpy="0 0 0" xyz="0 0 0" />
      <geometry>
        <cylinder length="0.065" radius="0.011" />
      </geometry>
    </collision>
  </link>
  <link name="FL_calflower1">
    <collision>
      <origin rpy="0 0 0" xyz="0 0 0" />
      <geometry>
        <cylinder length="0.03" radius="0.0155" />
      </geometry>
    </collision>
  </link>
  <link name="FL_foot">
    <inertial>
      <origin xyz="0 0 0" rpy="0 0 0" />
      <mass value="0.04" />
      <inertia ixx="9.6e-06" ixy="0" ixz="0" iyy="9.6e-06" iyz="0" izz="9.6e-06" />
    </inertial>
    <visual>
      <origin xyz="0 0 0" rpy="0 0 0" />
      <geometry>
        <mesh filename="../meshes/foot.dae" />
      </geometry>
    </visual>
    <collision>
      <origin rpy="0 0 0" xyz="-0.002 0 0" />
      <geometry>
        <sphere radius="0.022" />
      </geometry>
    </collision>
  </link>

  <link name="FR_hip">
    <inertial>
      <origin xyz="-0.0054 -0.00194 -0.000105" rpy="0 0 0" />
      <mass value="0.678" />
      <inertia ixx="0.00048" ixy="3.01E-06" ixz="1.11E-06" iyy="0.000884" iyz="1.42E-06" izz="0.000596" />
    </inertial>
    <visual>
      <origin xyz="0 0 0" rpy="3.1415 0 0" />
      <geometry>
        <mesh filename="../meshes/hip.dae" />
      </geometry>
    </visual>
    <collision>
      <origin rpy="1.5707963267948966 0 0" xyz="0 -0.08 0" />
      <geometry>
        <cylinder length="0.04" radius="0.046" />
      </geometry>
    </collision>
  </link>
  <link name="FR_thigh">
    <inertial>
      <origin xyz="-0.00374 0.0223 -0.0327" rpy="0 0 0" />
      <mass value="1.152" />
      <inertia ixx="0.00584" ixy="-8.72E-05" ixz="-0.000289" iyy="0.0058" iyz="-0.000808" izz="0.00103" />
    </inertial>
    <visual>
      <origin xyz="0 0 0" rpy="0 0 0" />
      <geometry>
        <mesh filename="../meshes/thigh_mirror.dae" />
      </geometry>
    </visual>
    <collision>
      <origin rpy="0 1.5707963267948966 0" xyz="0 0 -0.1065" />
      <geometry>
        <box size="0.11 0.0245 0.034" />
      </geometry>
    </collision>
  </link>
  <link name="FR_calf">
    <inertial>
      <origin xyz="0.00548 0.000975 -0.115" rpy="0 0 0" />
      <mass value="0.154" />
      <inertia ixx="0.00108" ixy="-3.4E-07" ixz="1.72E-05" iyy="0.0011" iyz="-8.28E-06" izz="3.29E-05" />
    </inertial>
    <visual>
      <origin xyz="0 0 0" rpy="0 0 0" />
      <geometry>
        <mesh filename="../meshes/calf_mirror.dae" />
      </geometry>
    </visual>
    <collision>
      <origin rpy="0 -0.2 0" xyz="0.01 0 -0.06" />
      <geometry>
        <cylinder length="0.12" radius="0.013" />
      </geometry>
    </collision>
  </link>
  <link name="FR_calflower">
    <collision>
      <origin rpy="0 0 0" xyz="0 0 0" />
      <geometry>
        <cylinder length="0.065" radius="0.011" />
      </geometry>
    </collision>
  </link>
  <link name="FR_calflower1">
    <collision>
      <origin rpy="0 0 0" xyz="0 0 0" />
      <geometry>
        <cylinder length="0.03" radius="0.0155" />
      </geometry>
    </collision>
  </link>
  <link name="FR_foot">
    <inertial>
      <origin xyz="0 0 0" rpy="0 0 0" />
      <mass value="0.04" />
      <inertia ixx="9.6e-06" ixy="0" ixz="0" iyy="9.6e-06" iyz="0" izz="9.6e-06" />
    </inertial>
    <visual>
      <origin xyz="0 0 0" rpy="0 0 0" />
      <geometry>
        <mesh filename="../meshes/foot.dae" />
      </geometry>
    </visual>
    <collision>
      <origin rpy="0 0 0" xyz="-0.002 0 0" />
      <geometry>
        <sphere radius="0.022" />
      </geometry>
    </collision>
  </link>

  <link name="RL_hip">
    <inertial>
      <origin xyz="0.0054 0.00194 -0.000105" rpy="0 0 0" />
      <mass value="0.678" />
      <inertia ixx="0.00048" ixy="3.01E-06" ixz="-1.11E-06" iyy="0.000884" iyz="-1.42E-06" izz="0.000596" />
    </inertial>
    <visual>
      <origin xyz="0 0 0" rpy="0 3.1415 0" />
      <geometry>
        <mesh filename="../meshes/hip.dae" />
      </geometry>
    </visual>
    <collision>
      <origin rpy="1.5707963267948966 0 0" xyz="0 0.08 0" />
      <geometry>
        <cylinder length="0.04" radius="0.046" />
      </geometry>
    </collision>
  </link>
  <link name="RL_thigh">
    <inertial>
      <origin xyz="-0.00374 -0.0223 -0.0327" rpy="0 0 0" />
      <mass value="1.152" />
      <inertia ixx="0.00584" ixy="8.72E-05" ixz="-0.000289" iyy="0.0058" iyz="0.000808" izz="0.00103" />
    </inertial>
    <visual>
      <origin xyz="0 0 0" rpy="0 0 0" />
      <geometry>
        <mesh filename="../meshes/thigh.dae" />
      </geometry>
    </visual>
    <collision>
      <origin rpy="0 1.5707963267948966 0" xyz="0 0 -0.1065" />
      <geometry>
        <box size="0.11 0.0245 0.034" />
      </geometry>
    </collision>
  </link>
  <link name="RL_calf">
    <inertial>
      <origin xyz="0.00548 -0.000975 -0.115" rpy="0 0 0" />
      <mass value="0.154" />
      <inertia ixx="0.00108" ixy="3.4E-07" ixz="1.72E-05" iyy="0.0011" iyz="8.28E-06" izz="3.29E-05" />
    </inertial>
    <visual>
      <origin xyz="0 0 0" rpy="0 0 0" />
      <geometry>
        <mesh filename="../meshes/calf.dae" />
      </geometry>
    </visual>
    <collision>
      <origin rpy="0 -0.2 0" xyz="0.01 0 -0.06" />
      <geometry>
        <cylinder length="0.12" radius="0.013" />
      </geometry>
    </collision>
  </link>
  <link name="RL_calflower">
    <collision>
      <origin rpy="0 0 0" xyz="0 0 0" />
      <geometry>
        <cylinder length="0.065" radius="0.011" />
      </geometry>
    </collision>
  </link>
  <link name="RL_calflower1">
    <collision>
      <origin rpy="0 0 0" xyz="0 0 0" />
      <geometry>
        <cylinder length="0.03" radius="0.0155" />
      </geometry>
    </collision>
  </link>
  <link name="RL_foot">
    <inertial>
      <origin xyz="0 0 0" rpy="0 0 0" />
      <mass value="0.04" />
      <inertia ixx="9.6e-06" ixy="0" ixz="0" iyy="9.6e-06" iyz="0" izz="9.6e-06" />
    </inertial>
    <visual>
      <origin xyz="0 0 0" rpy="0 0 0" />
      <geometry>
        <mesh filename="../meshes/foot.dae" />
      </geometry>
    </visual>
    <collision>
      <origin rpy="0 0 0" xyz="-0.002 0 0" />
      <geometry>
        <sphere radius="0.022" />
      </geometry>
    </collision>
  </link>

  <link name="RR_hip">
    <inertial>
      <origin xyz="0.0054 -0.00194 -0.000105" rpy="0 0 0" />
      <mass value="0.678" />
      <inertia ixx="0.00048" ixy="-3.01E-06" ixz="-1.11E-06" iyy="0.000884" iyz="1.42E-06" izz="0.000596" />
    </inertial>
    <visual>
      <origin xyz="0 0 0" rpy="3.1415 3.1415 0" />
      <geometry>
        <mesh filename="../meshes/hip.dae" />
      </geometry>
    </visual>
    <collision>
      <origin rpy="1.5707963267948966 0 0" xyz="0 -0.08 0" />
      <geometry>
        <cylinder length="0.04" radius="0.046" />
      </geometry>
    </collision>
  </link>
  <link name="RR_thigh">
    <inertial>
      <origin xyz="-0.00374 0.0223 -0.0327" rpy="0 0 0" />
      <mass value="1.152" />
      <inertia ixx="0.00584" ixy="-8.72E-05" ixz="-0.000289" iyy="0.0058" iyz="-0.000808" izz="0.00103" />
    </inertial>
    <visual>
      <origin xyz="0 0 0" rpy="0 0 0" />
      <geometry>
        <mesh filename="../meshes/thigh_mirror.dae" />
      </geometry>
    </visual>
    <collision>
      <origin rpy="0 1.5707963267948966 0" xyz="0 0 -0.1065" />
      <geometry>
        <box size="0.11 0.0245 0.034" />
      </geometry>
    </collision>
  </link>
  <link name="RR_calf">
    <inertial>
      <origin xyz="0.00548 0.000975 -0.115" rpy="0 0 0" />
      <mass value="0.154" />
      <inertia ixx="0.00108" ixy="-3.4E-07" ixz="1.72E-05" iyy="0.0011" iyz="-8.28E-06" izz="3.29E-05" />
    </inertial>
    <visual>
      <origin xyz="0 0 0" rpy="0 0 0" />
      <geometry>
        <mesh filename="../meshes/calf_mirror.dae" />
      </geometry>
    </visual>
    <collision>
      <origin rpy="0 -0.2 0" xyz="0.01 0 -0.06" />
      <geometry>
        <cylinder length="0.12" radius="0.013" />
      </geometry>
    </collision>
  </link>
  <link name="RR_calflower">
    <collision>
      <origin rpy="0 0 0" xyz="0 0 0" />
      <geometry>
        <cylinder length="0.065" radius="0.011" />
      </geometry>
    </collision>
  </link>
  <link name="RR_calflower1">
    <collision>
      <origin rpy="0 0 0" xyz="0 0 0" />
      <geometry>
        <cylinder length="0.03" radius="0.0155" />
      </geometry>
    </collision>
  </link>
  <link name="RR_foot">
    <inertial>
      <origin xyz="0 0 0" rpy="0 0 0" />
      <mass value="0.04" />
      <inertia ixx="9.6e-06" ixy="0" ixz="0" iyy="9.6e-06" iyz="0" izz="9.6e-06" />
    </inertial>
    <visual>
      <origin xyz="0 0 0" rpy="0 0 0" />
      <geometry>
        <mesh filename="../meshes/foot.dae" />
      </geometry>
    </visual>
    <collision>
      <origin rpy="0 0 0" xyz="-0.002 0 0" />
      <geometry>
        <sphere radius="0.022" />
      </geometry>
    </collision>
  </link>

  <link name="imu">
    <inertial>
      <origin xyz="0 0 0" rpy="0 0 0" />
      <mass value="0" />
      <inertia ixx="0" ixy="0" ixz="0" iyy="0" iyz="0" izz="0" />
    </inertial>
  </link>
  <link name="radar">
    <inertial>
      <origin xyz="0 0 0" rpy="0 0 0" />
      <mass value="0" />
      <inertia ixx="0" ixy="0" ixz="0" iyy="0" iyz="0" izz="0" />
    </inertial>
  </link>

  <!-- ═══════════════════════ BASE / HEAD JOINTS ═══════════════════════ -->
  <joint name="Head_upper_joint" type="fixed" dont_collapse="true">
    <origin xyz="0.285 0 0.01" rpy="0 0 0" />
    <parent link="base" />
    <child link="Head_upper" />
    <axis xyz="0 0 0" />
  </joint>
  <joint name="Head_lower_joint" type="fixed" dont_collapse="true">
    <origin xyz="0.008 0 -0.07" rpy="0 0 0" />
    <parent link="Head_upper" />
    <child link="Head_lower" />
    <axis xyz="0 0 0" />
  </joint>
  <joint name="imu_joint" type="fixed">
    <origin xyz="-0.02557 0 0.04232" rpy="0 0 0" />
    <parent link="base" />
    <child link="imu" />
    <axis xyz="0 0 0" />
  </joint>
  <joint name="radar_joint" type="fixed">
    <origin xyz="0.28945 0 -0.046825" rpy="0 2.8782 0" />
    <parent link="base" />
    <child link="radar" />
    <axis xyz="0 0 0" />
  </joint>

  <!-- ═══════════════════════ LEG JOINTS ═══════════════════════ -->
  <joint name="FL_hip_joint" type="revolute">
    <origin xyz="0.1934 0.0465 0" rpy="0 0 0" />
    <parent link="base" />
    <child link="FL_hip" />
    <axis xyz="1 0 0" />
    <limit lower="-1.0472" upper="1.0472" effort="23.7" velocity="30.1" />
  </joint>
  <joint name="FL_thigh_joint" type="revolute">
    <origin xyz="0 0.0955 0" rpy="0 0 0" />
    <parent link="FL_hip" />
    <child link="FL_thigh" />
    <axis xyz="0 1 0" />
    <limit lower="-1.5708" upper="3.4907" effort="23.7" velocity="30.1" />
  </joint>
  <joint name="FL_calf_joint" type="revolute">
    <origin xyz="0 0 -0.213" rpy="0 0 0" />
    <parent link="FL_thigh" />
    <child link="FL_calf" />
    <axis xyz="0 1 0" />
    <limit lower="-2.7227" upper="-0.83776" effort="35.55" velocity="20.07" />
  </joint>
  <joint name="FL_calflower_joint" type="fixed">
    <origin xyz="0.020 0 -0.148" rpy="0 0.05 0" />
    <parent link="FL_calf" />
    <child link="FL_calflower" />
    <axis xyz="0 0 0" />
  </joint>
  <joint name="FL_calflower1_joint" type="fixed">
    <origin xyz="-0.01 0 -0.04" rpy="0 0.48 0" />
    <parent link="FL_calflower" />
    <child link="FL_calflower1" />
    <axis xyz="0 0 0" />
  </joint>
  <joint name="FL_foot_joint" type="fixed" dont_collapse="true">
    <origin xyz="0 0 -0.213" rpy="0 0 0" />
    <parent link="FL_calf" />
    <child link="FL_foot" />
    <axis xyz="0 0 0" />
  </joint>

  <joint name="FR_hip_joint" type="revolute">
    <origin xyz="0.1934 -0.0465 0" rpy="0 0 0" />
    <parent link="base" />
    <child link="FR_hip" />
    <axis xyz="1 0 0" />
    <limit lower="-1.0472" upper="1.0472" effort="23.7" velocity="30.1" />
  </joint>
  <joint name="FR_thigh_joint" type="revolute">
    <origin xyz="0 -0.0955 0" rpy="0 0 0" />
    <parent link="FR_hip" />
    <child link="FR_thigh" />
    <axis xyz="0 1 0" />
    <limit lower="-1.5708" upper="3.4907" effort="23.7" velocity="30.1" />
  </joint>
  <joint name="FR_calf_joint" type="revolute">
    <origin xyz="0 0 -0.213" rpy="0 0 0" />
    <parent link="FR_thigh" />
    <child link="FR_calf" />
    <axis xyz="0 1 0" />
    <limit lower="-2.7227" upper="-0.83776" effort="35.55" velocity="20.07" />
  </joint>
  <joint name="FR_calflower_joint" type="fixed">
    <origin xyz="0.020 0 -0.148" rpy="0 0.05 0" />
    <parent link="FR_calf" />
    <child link="FR_calflower" />
    <axis xyz="0 0 0" />
  </joint>
  <joint name="FR_calflower1_joint" type="fixed">
    <origin xyz="-0.01 0 -0.04" rpy="0 0.48 0" />
    <parent link="FR_calflower" />
    <child link="FR_calflower1" />
    <axis xyz="0 0 0" />
  </joint>
  <joint name="FR_foot_joint" type="fixed" dont_collapse="true">
    <origin xyz="0 0 -0.213" rpy="0 0 0" />
    <parent link="FR_calf" />
    <child link="FR_foot" />
    <axis xyz="0 0 0" />
  </joint>

  <joint name="RL_hip_joint" type="revolute">
    <origin xyz="-0.1934 0.0465 0" rpy="0 0 0" />
    <parent link="base" />
    <child link="RL_hip" />
    <axis xyz="1 0 0" />
    <limit lower="-1.0472" upper="1.0472" effort="23.7" velocity="30.1" />
  </joint>
  <joint name="RL_thigh_joint" type="revolute">
    <origin xyz="0 0.0955 0" rpy="0 0 0" />
    <parent link="RL_hip" />
    <child link="RL_thigh" />
    <axis xyz="0 1 0" />
    <limit lower="-0.5236" upper="4.5379" effort="23.7" velocity="30.1" />
  </joint>
  <joint name="RL_calf_joint" type="revolute">
    <origin xyz="0 0 -0.213" rpy="0 0 0" />
    <parent link="RL_thigh" />
    <child link="RL_calf" />
    <axis xyz="0 1 0" />
    <limit lower="-2.7227" upper="-0.83776" effort="35.55" velocity="20.07" />
  </joint>
  <joint name="RL_calflower_joint" type="fixed">
    <origin xyz="0.020 0 -0.148" rpy="0 0.05 0" />
    <parent link="RL_calf" />
    <child link="RL_calflower" />
    <axis xyz="0 0 0" />
  </joint>
  <joint name="RL_calflower1_joint" type="fixed">
    <origin xyz="-0.01 0 -0.04" rpy="0 0.48 0" />
    <parent link="RL_calflower" />
    <child link="RL_calflower1" />
    <axis xyz="0 0 0" />
  </joint>
  <joint name="RL_foot_joint" type="fixed" dont_collapse="true">
    <origin xyz="0 0 -0.213" rpy="0 0 0" />
    <parent link="RL_calf" />
    <child link="RL_foot" />
    <axis xyz="0 0 0" />
  </joint>

  <joint name="RR_hip_joint" type="revolute">
    <origin xyz="-0.1934 -0.0465 0" rpy="0 0 0" />
    <parent link="base" />
    <child link="RR_hip" />
    <axis xyz="1 0 0" />
    <limit lower="-1.0472" upper="1.0472" effort="23.7" velocity="30.1" />
  </joint>
  <joint name="RR_thigh_joint" type="revolute">
    <origin xyz="0 -0.0955 0" rpy="0 0 0" />
    <parent link="RR_hip" />
    <child link="RR_thigh" />
    <axis xyz="0 1 0" />
    <limit lower="-0.5236" upper="4.5379" effort="23.7" velocity="30.1" />
  </joint>
  <joint name="RR_calf_joint" type="revolute">
    <origin xyz="0 0 -0.213" rpy="0 0 0" />
    <parent link="RR_thigh" />
    <child link="RR_calf" />
    <axis xyz="0 1 0" />
    <limit lower="-2.7227" upper="-0.83776" effort="35.55" velocity="20.07" />
  </joint>
  <joint name="RR_calflower_joint" type="fixed">
    <origin xyz="0.020 0 -0.148" rpy="0 0.05 0" />
    <parent link="RR_calf" />
    <child link="RR_calflower" />
    <axis xyz="0 0 0" />
  </joint>
  <joint name="RR_calflower1_joint" type="fixed">
    <origin xyz="-0.01 0 -0.04" rpy="0 0.48 0" />
    <parent link="RR_calflower" />
    <child link="RR_calflower1" />
    <axis xyz="0 0 0" />
  </joint>
  <joint name="RR_foot_joint" type="fixed" dont_collapse="true">
    <origin xyz="0 0 -0.213" rpy="0 0 0" />
    <parent link="RR_calf" />
    <child link="RR_foot" />
    <axis xyz="0 0 0" />
  </joint>

  <!-- ═══════════════════════ D1 ARM ═══════════════════════ -->
  <link name="base_link">
    <inertial>
      <origin xyz="3.43E-03 -0.0000025 0.047074" rpy="0 0 0" />
      <mass value="1.287" />
      <inertia ixx="0.00218" ixy="2.19e-06" ixz="8.55e-05"
               iyy="2.32e-03" iyz="1.20e-06" izz="3.20e-03" />
    </inertial>
    <visual>
      <origin xyz="0 0 0" rpy="-1.5707963268 0 0" />
      <geometry>
        <mesh filename="../meshes/D1_meshes/base_link.STL" />
      </geometry>
      <material name="">
        <color rgba="0.79216 0.81961 0.93333 1" />
      </material>
    </visual>
    <collision>
      <origin xyz="0 0 0" rpy="0 0 0" />
      <geometry>
        <mesh filename="../meshes/D1_meshes/base_link.STL" />
      </geometry>
    </collision>
  </link>

  <link name="Empty_Link1">
    <inertial>
      <origin xyz="-0.000838 8.01E-05 0.022211" rpy="0 0 0" />
      <mass value="0.408" />
      <inertia ixx="4.14e-04" ixy="-3.07e-07" ixz="1.65e-06"
               iyy="3.98e-04" iyz="-1.62e-06" izz="2.92e-04" />
    </inertial>
    <visual>
      <origin xyz="0 0 0" rpy="-1.5707963268 0 0" />
      <geometry>
        <mesh filename="../meshes/D1_meshes/Empty_Link1.STL" />
      </geometry>
      <material name="">
        <color rgba="0.79216 0.81961 0.93333 1" />
      </material>
    </visual>
    <collision>
      <origin xyz="0 0 0" rpy="0 0 0" />
      <geometry>
        <mesh filename="../meshes/D1_meshes/Empty_Link1.STL" />
      </geometry>
    </collision>
  </link>
  <joint name="Z_Joint1" type="revolute">
    <origin xyz="0 0 0.0738" rpy="0 0 0" />
    <parent link="base_link" />
    <child link="Empty_Link1" />
    <axis xyz="0 0 -1" />
    <limit lower="-2.36" upper="2.36" effort="10." velocity="5" />
  </joint>

  <link name="Empty_Link2">
    <inertial>
      <origin xyz="5.7801E-05 0.027243 0.19413" rpy="0 0 0" />
      <mass value="0.472" />
      <inertia ixx="1.40e-04" ixy="-3.74e-06" ixz="1.46e-06"
               iyy="3.44e-03" iyz="-3.74e-06" izz="3.51e-03" />
    </inertial>
    <visual>
      <origin xyz="0 0 0" rpy="-1.5707963268 0 0" />
      <geometry>
        <mesh filename="../meshes/D1_meshes/Empty_Link2.STL" />
      </geometry>
      <material name="">
        <color rgba="0.79216 0.81961 0.93333 1" />
      </material>
    </visual>
    <collision>
      <origin xyz="0 0 0" rpy="0 0 0" />
      <geometry>
        <mesh filename="../meshes/D1_meshes/Empty_Link2.STL" />
      </geometry>
    </collision>
  </link>
  <joint name="Z_Joint2" type="revolute">
    <origin xyz="0 -0.0276 0.0578" rpy="0 -0.0 0" />
    <parent link="Empty_Link1" />
    <child link="Empty_Link2" />
    <axis xyz="0 1 0" />
    <limit lower="-1.57" upper="1.57" effort="10." velocity="5" />
  </joint>

  <link name="Empty_Link3">
    <inertial>
      <origin xyz="0.016076 0.027468 0.043875" rpy="0 0 0" />
      <mass value="0.162" />
      <inertia ixx="6.08e-05" ixy="-2.01e-7" ixz="-7.09e-07"
               iyy="8.60e-05" iyz="-3.24e-7" izz="6.99e-05" />
    </inertial>
    <visual>
      <origin xyz="0 0 0" rpy="-1.5707963268 0 0" />
      <geometry>
        <mesh filename="../meshes/D1_meshes/Empty_Link3.STL" />
      </geometry>
      <material name="">
        <color rgba="0.79216 0.81961 0.93333 1" />
      </material>
    </visual>
    <collision>
      <origin xyz="0 0 0" rpy="0 0 0" />
      <geometry>
        <mesh filename="../meshes/D1_meshes/Empty_Link3.STL" />
      </geometry>
    </collision>
  </link>
  <joint name="Z_Joint3" type="revolute">
    <origin xyz="0 -0.0004 0.27" rpy="0 0.0 0" />
    <parent link="Empty_Link2" />
    <child link="Empty_Link3" />
    <axis xyz="0 1 0" />
    <limit lower="-1.57" upper="1.57" effort="10." velocity="5" />
  </joint>

  <link name="Empty_Link4">
    <inertial>
      <origin xyz="0.088538 5.32E-05 0.000443" rpy="0 0 0" />
      <mass value="0.234" />
      <inertia ixx="5.00e-05" ixy="4.14e-06" ixz="-5.21e-07"
               iyy="7.16e-04" iyz="-2.22e-07" izz="7.47e-04" />
    </inertial>
    <visual>
      <origin xyz="0 0 0" rpy="-1.5707963268 0 0" />
      <geometry>
        <mesh filename="../meshes/D1_meshes/Empty_Link4.STL" />
      </geometry>
      <material name="">
        <color rgba="0.79216 0.81961 0.93333 1" />
      </material>
    </visual>
    <collision>
      <origin xyz="0 0 0" rpy="0 0 0" />
      <geometry>
        <mesh filename="../meshes/D1_meshes/Empty_Link4.STL" />
      </geometry>
    </collision>
  </link>
  <joint name="Z_Joint4" type="revolute">
    <origin xyz="0.05 0.0275 0.041325" rpy="0 0 0" />
    <parent link="Empty_Link3" />
    <child link="Empty_Link4" />
    <axis xyz="1 0 0" />
    <limit lower="-2.36" upper="2.36" effort="5." velocity="5" />
  </joint>

  <link name="Empty_Link5">
    <inertial>
      <origin xyz="0.044236 0.025833 0.005276" rpy="0 0 0" />
      <mass value="0.151" />
      <inertia ixx="4.08e-05" ixy="2.94e-07" ixz="8.14e-06"
               iyy="7.27e-05" iyz="-9.90e-08" izz="6.44e-05" />
    </inertial>
    <visual>
      <origin xyz="0 0 0" rpy="-1.5707963268 0 0" />
      <geometry>
        <mesh filename="../meshes/D1_meshes/Empty_Link5.STL" />
      </geometry>
      <material name="">
        <color rgba="0.79216 0.81961 0.93333 1" />
      </material>
    </visual>
    <collision>
      <origin xyz="0 0 0" rpy="0 0 0" />
      <geometry>
        <mesh filename="../meshes/D1_meshes/Empty_Link5.STL" />
      </geometry>
    </collision>
  </link>
  <joint name="Z_Joint5" type="revolute">
    <origin xyz="0.15468 -0.0258 0.0001" rpy="0 0 0" />
    <parent link="Empty_Link4" />
    <child link="Empty_Link5" />
    <axis xyz="0 1 0" />
    <limit lower="-1.57" upper="1.57" effort="5." velocity="5" />
  </joint>

  <!-- Wrist -->
  <link name="Empty_Link6">
    <inertial>
      <origin xyz="0.03835 -0.000037 0.005894" rpy="0 0 0" />
      <mass value="0.173" />
      <inertia ixx="1.26e-04" ixy="-2.13e-07" ixz="9.81e-06"
               iyy="1.15e-04"  iyz="-3.35e-07" izz="1.85e-04" />
    </inertial>
    <visual>
      <origin xyz="0 0 0" rpy="-1.5707963268 0 0" />
      <geometry>
        <mesh filename="../meshes/D1_meshes/Empty_Link6.STL" />
      </geometry>
      <material name="">
        <color rgba="0.79216 0.81961 0.93333 1" />
      </material>
    </visual>
    <collision>
      <origin xyz="0 0 0" rpy="0 0 0" />
      <geometry>
        <mesh filename="../meshes/D1_meshes/Empty_Link6.STL" />
      </geometry>
    </collision>
  </link>
  <joint name="Z_Joint6" type="revolute">
    <origin xyz="0.0777 0.025822 -0.0010718" rpy="0 0 0" />
    <parent link="Empty_Link5" />
    <child link="Empty_Link6" />
    <axis xyz="1 0 0" />
    <limit lower="-2.36" upper="2.36" effort="5." velocity="5" />
  </joint>

  <!-- ═══════════════════════ UMI GRIPPER ═══════════════════════
       Finger links, elastomers, and EE frame from go2d1_umi_ee.urdf.
       Joint names kept as Z_Joint_L / Z_Joint_R for config compatibility.
       Link names Empty_Link_L / Empty_Link_R preserved for body-count stability.
       end_effector link and ZZEnd_Effector joint kept for gripper_name compatibility.
  ══════════════════════════════════════════════════════════════ -->

  <!-- Left finger -->
  <link name="Empty_Link_L">
    <inertial>
      <origin xyz="0.018562 -0.0073492 -0.0034988" rpy="0 0 0" />
      <mass value="0.01333" />
      <inertia ixx="1.0229E-06" ixy="-1.5002E-07" ixz="1.3407E-11"
               iyy="2.3789E-06" iyz="-1.3846E-14" izz="1.8134E-06" />
    </inertial>
    <visual>
      <origin xyz="0 0 0" rpy="0 0 0" />
      <geometry>
        <mesh filename="../meshes/D1_meshes/finger_left.obj" scale="0.001 0.001 0.001" />
      </geometry>
      <material name="orange" />
    </visual>
    <collision>
      <origin xyz="0 0 0" rpy="0 0 0" />
      <geometry>
        <mesh filename="../meshes/D1_meshes/finger_left.STL" scale="0.001 0.001 0.001" />
      </geometry>
    </collision>
  </link>

  <joint name="Z_Joint_L" type="prismatic">
    <origin xyz="0.0718 -0.033778 0.0031" rpy="0 0 0" />
    <parent link="Empty_Link6" />
    <child link="Empty_Link_L" />
    <axis xyz="0 1 0" />
    <limit lower="0" upper="0.033" effort="15" velocity="0.02" />
  </joint>

  <!-- Left elastomer (flat pad) -->
  <link name="elastomer_left">
    <visual>
      <origin rpy="-1.5707963268 0 0" xyz="0 0 0" />
      <geometry>
        <mesh filename="../meshes/D1_meshes/flat_pad.obj" />
      </geometry>
      <material name="brown" />
    </visual>
    <collision>
      <origin rpy="0 0 0" xyz="0 0 0" />
      <geometry>
        <mesh filename="../meshes/D1_meshes/flat_pad.obj" />
      </geometry>
    </collision>
    <inertial>
      <origin xyz="0 0 0" rpy="0 0 0" />
      <mass value="0.001" />
      <inertia ixx="1e-7" ixy="0" ixz="0" iyy="1e-7" iyz="0" izz="1e-7" />
    </inertial>
  </link>

  <joint name="ZZelastomer_joint_left" type="fixed" dont_collapse="true">
    <origin rpy="3.14 1.57 0" xyz="0.04932 -0.0005 -0.0035" />
    <parent link="Empty_Link_L" />
    <child link="elastomer_left" />
    <axis xyz="0 0 0" />
  </joint>

  <!-- Right finger -->
  <link name="Empty_Link_R">
    <inertial>
      <origin xyz="0.018562 0.0073492 -0.0035012" rpy="0 0 0" />
      <mass value="0.01333" />
      <inertia ixx="1.0229E-06" ixy="1.5002E-07" ixz="-1.3407E-11"
               iyy="2.3789E-06" iyz="-1.3811E-14" izz="1.8134E-06" />
    </inertial>
    <visual>
      <origin xyz="0 0 0" rpy="0 0 0" />
      <geometry>
        <mesh filename="../meshes/D1_meshes/finger_right.obj" scale="0.001 0.001 0.001" />
      </geometry>
      <material name="orange" />
    </visual>
    <collision>
      <origin xyz="0 0 0" rpy="0 0 0" />
      <geometry>
        <mesh filename="../meshes/D1_meshes/finger_right.STL" scale="0.001 0.001 0.001" />
      </geometry>
    </collision>
  </link>

  <joint name="Z_Joint_R" type="prismatic">
    <origin xyz="0.0718 0.033022 0.0031" rpy="0 0 0" />
    <parent link="Empty_Link6" />
    <child link="Empty_Link_R" />
    <axis xyz="0 -1 0" />
    <limit lower="0" upper="0.03" effort="15" velocity="0.02" />
  </joint>

  <!-- Right elastomer (flat pad) -->
  <link name="elastomer_right">
    <visual>
      <origin rpy="-1.5707963268 0 0" xyz="0 0 0" />
      <geometry>
        <mesh filename="../meshes/D1_meshes/flat_pad.obj" />
      </geometry>
      <material name="brown" />
    </visual>
    <collision>
      <origin rpy="0 0 0" xyz="0 0 0" />
      <geometry>
        <mesh filename="../meshes/D1_meshes/flat_pad.obj" />
      </geometry>
    </collision>
    <inertial>
      <origin xyz="0 0 0" rpy="0 0 0" />
      <mass value="0.001" />
      <inertia ixx="1e-7" ixy="0" ixz="0" iyy="1e-7" iyz="0" izz="1e-7" />
    </inertial>
  </link>

  <joint name="ZZelastomer_joint_right" type="fixed" dont_collapse="true">
    <origin rpy="0 -1.57 0" xyz="0.04932 0.0005 -0.0035" />
    <parent link="Empty_Link_R" />
    <child link="elastomer_right" />
    <axis xyz="0 0 0" />
  </joint>

  <!-- EE frame — name/position kept identical to go2d1_tac.urdf for policy compatibility -->
  <joint name="ZZEnd_Effector" type="fixed" dont_collapse="true">
    <origin rpy="0 -1.57 0" xyz="0.1 0 0" />
    <parent link="Empty_Link6" />
    <child link="end_effector" />
    <axis xyz="0 0 0" />
  </joint>
  <link name="end_effector">
    <inertial>
      <origin rpy="0 0 0" xyz="0 0 0" />
      <mass value="0.001" />
      <inertia ixx="9.6e-06" ixy="0" ixz="0" iyy="9.6e-06" iyz="0" izz="9.6e-06" />
    </inertial>
  </link>

  <!-- ═══════════════════════ ARM MOUNT ═══════════════════════ -->
  <joint name="d1_mount" type="fixed" dont_collapse="true">
    <origin rpy="0 0 0" xyz="-0.02 0 0.057" />
    <parent link="base" />
    <child link="base_link" />
  </joint>

</robot>
